Workbook

Sheet Key
A1: Orvanna Builder compensation plan: the mechanics
A2: Numbers and rules only. Source of truth: ORVANNA-BUILDER-PLAN-SPEC.md v1.2.2 and COMP-PLAN-SPEC.md v1.3.
A4: Sheet | B4: What is on it
A5: Parameters | B5: Every rate and dial in one place. The only cells anyone should change.
A6: Ranks and gates | B6: The one qualification gate, the five ranks, the paid depth each rank unlocks.
A7: Layer 1 spine | B7: Unilevel level pay: 10/5/5/3/2 percent, and the arithmetic that makes the spine always fit.
A8: Layer 2 overrides | B8: Builder overrides: the two-generation boundary walk, stated as executable steps.
A9: Layer 3 second leg | B9: The second-strongest-leg bonus and its active-leg multiplier.
A10: Law B waterfall | B10: The per-order cap: pool, seniority, proration factors, the invariant.
A11: Worked example | B11: The ten-member gate fixture, live: every source, every factor, every check to the cent.
A12: Cap calculator | B12: Type an order price, see the pool, the spine's maximum bite, and the headroom left.
A13: Measured results | B13: What the plan actually paid on the seeded census: cost, proration, development premium.
A14: Guardrails | B14: Anti-gaming arithmetic: what every known attack returns per dollar spent.
A15: Open items | B15: The eight parameters still on default, waiting on a ruling.
A17: Term | B17: Written out in full | C17: Meaning here
A18: PV | B18: Personal Volume | C18: Point value carried by a product. In this plan PV equals dollars, one to one.
A19: SV | B19: Sales Volume | C19: A member's own PV for the month, across everything booked to their account.
A20: CV | B20: Commissionable Volume | C20: 0.80 times SV, rounded half up. Every commission percentage applies to CV.
A21: TV | B21: Team Volume | C21: Sum of SV of everyone strictly below the member. Excludes their own SV.
A22: Group CV | B22: Group Commissionable Volume | C22: A member's own CV plus the CV of their entire subtree, full depth.
A23: Leg | B23: Leg | C23: One personally sponsored member plus that member's whole subtree.
A24: Active leg | B24: Active leg | C24: A leg whose frontline member is qualified this month.
A25: Source | B25: Source member-month | C25: The member whose volume a commission is being paid ON.
A26: Earner | B26: Earner | C26: The member being paid.
A27: Breakage | B27: Breakage | C27: Volume nobody was paid on: earner unqualified, or the level was out of reach.
A28: Proration | B28: Proration | C28: A layer 2 or layer 3 claim paid at less than face value because the cap bound.
A30: Cell colour | B30: Means
A31: Blue text | B31: Hardcoded input or lever. Change these.
A32: Green text | B32: Pulled from another sheet in this workbook.
A33: Black text | B33: Formula. Do not overwrite.
A34: Pink fill | B34: The cap is binding on that row.

Sheet Parameters
A1: Parameters
A2: Rates of record are the calibrated values in force. Draft rates are kept because the gate fixture is contracted at them.
A4: Parameter | B4: Rate of record | C4: Draft rate | D4: Applies to | E4: Fixed or tunable
A5: Level 1 rate | B5: 0.1 | C5: 0.1 | D5: Layer 1 spine, source at tree distance 1 | E5: Fixed: the live plan
A6: Level 2 rate | B6: 0.05 | C6: 0.05 | D6: Layer 1 spine, tree distance 2 | E6: Fixed: the live plan
A7: Level 3 rate | B7: 0.05 | C7: 0.05 | D7: Layer 1 spine, tree distance 3 | E7: Fixed: the live plan
A8: Level 4 rate | B8: 0.03 | C8: 0.03 | D8: Layer 1 spine, tree distance 4 | E8: Fixed: the live plan
A9: Level 5 rate | B9: 0.02 | C9: 0.02 | D9: Layer 1 spine, tree distance 5 | E9: Fixed: the live plan
A10: Generation 1 override rate | B10: 0.015 | C10: 0.04 | D10: Layer 2, on a Builder's group CV | E10: Tunable
A11: Generation 2 override rate | B11: 0.01 | C11: 0.05 | D11: Layer 2, second generation | E11: Tunable
A12: Second-leg base rate | B12: 0.02 | C12: 0.05 | D12: Layer 3, on the second-strongest leg's CV | E12: Tunable
A13: Leg multiplier, 2 active legs | B13: 1 | C13: 1 | D13: Layer 3 step | E13: Tunable
A14: Leg multiplier, 3 active legs | B14: 1.15 | C14: 1.15 | D14: Layer 3 step | E14: Tunable
A15: Leg multiplier, 4 or more | B15: 1.25 | C15: 1.25 | D15: Layer 3 step | E15: Tunable
A16: Pool rate | B16: 0.25 | C16: 0.25 | D16: Law B: pool = pool rate times source CV | E16: Tunable, but see Open items
... A18: CV factor | B18: 0.8 | C18: 0.8 | D18: CV = CV factor times SV | E18: Fixed
A20: Seniority order in the cap | B20: Position | C20: Prorates when the pool runs out?
A21: Layer 1, the spine | B21: First | C21: Never. It cannot exceed the pool. See Layer 1 spine.
A22: Layer 2, Builder overrides | B22: Second | C22: Yes. Generations 1 and 2 share one class, pro rata.
A23: Layer 3, second-leg bonus | B23: Third | C23: Yes. Paid from whatever layers 1 and 2 left.
A25: The calibration of 2026-08-16 scaled the three tunable rates by one common factor of 0.4075 (window midpoint 3.0 divided by the measured increment 7.3627) and rounded each to the nearest 0.005.
A26: Draft rates are retained because the ten-member gate fixture is contracted at them. Every run records the rates it used, so the fixture's arithmetic is the contract, not the calibration.

Sheet Ranks and gates
A1: Ranks and gates
A2: Recomputed from scratch every month. Nothing is banked, grandfathered, or carried forward.
A4: Rank | B4: Qualified? | C4: Team Volume needed | D4: Leg requirement | E4: Paid depth | F4: Levels the member is paid on
A5: Member | B5: not required | C5: none | D5: none | E5: 1 | F5: Level 1 only
A6: Builder | B6: yes | C6: none | D6: 2 or more active legs | E6: 2 | F6: Levels 1 to 2
A7: Leader | B7: yes | C7: 2500 | D7: 3 or more active legs | E7: 3 | F7: Levels 1 to 3
A8: Director | B8: yes | C8: 10000 | D8: 2 or more legs, each containing a Builder or higher | E8: 4 | F8: Levels 1 to 4
A9: Executive | B9: yes | C9: 40000 | D9: 2 or more legs, each containing a Leader or higher | E9: 5 | F9: Levels 1 to 5
A11: Rule | B11: Value
A12: The qualification gate | B12: SV greater than or equal to 100.00 in the month. One threshold, both jobs.
A13: Ways to meet it | B13: One domain agent at 100 PV, or two support agents at 50 PV each, or any mix reaching 100.
A14: Every threshold | B14: Greater than or equal to. Exactly 100.00 qualifies. Exactly 2,500 is Leader.
A15: Rank held | B15: The highest rank whose requirements all hold in the same month.
A16: Grace months | B16: None in version 1. Qualification resets every month.
A17: Earner must be qualified | B17: Yes, on all three layers. An unqualified member earns nothing.
A18: Source must be qualified | B18: No. All CV pays upline whoever generated it.
A19: Compression | B19: None in version 1. Levels are plain tree distance.
A20: Placement tree | B20: None anywhere in this plan. Legs are the real sponsor genealogy.
A21: Customer volume | B21: Books to the referring member's account, so it counts toward their SV and qualification.
A23: Product | B23: Price per month | C23: PV per month | D23: Counts toward the gate
A24: Domain agent (Payment, Shipping, Pricing, Inventory, Marketing, Tax) | B24: 100 | C24: 100 | D24: Qualifies on its own
A25: Support agent (Software Engineer, Quality Assurance, Secretary, Chief Executive, Accounting, Customer Care) | B25: 50 | C25: 50 | D25: Two of them qualify
A26: PV equals dollars one to one. A subscription grants its PV every month it is active; cancel and the PV stops.

Sheet Layer 1 spine
A1: Layer 1, the spine: unilevel level pay
A2: Identical to the live plan, unchanged. A member who understands today's plan already understands this layer.
A4: Level | B4: Rate | C4: Paid to | D4: Unlocked at rank | E4: On a source with CV 80.00 | F4: On a source with CV 1,000.00
A5: 1 | B5: =Parameters!$B$5 -> 0.1 | C5: The sponsor | D5: Member | E5: =$B5*80 -> 8 | F5: =$B5*1000 -> 100
A6: 2 | B6: =Parameters!$B$6 -> 0.05 | C6: The sponsor's sponsor | D6: Builder | E6: =$B6*80 -> 4 | F6: =$B6*1000 -> 50
A7: 3 | B7: =Parameters!$B$7 -> 0.05 | C7: Three up | D7: Leader | E7: =$B7*80 -> 4 | F7: =$B7*1000 -> 50
A8: 4 | B8: =Parameters!$B$8 -> 0.03 | C8: Four up | D8: Director | E8: =$B8*80 -> 2.4 | F8: =$B8*1000 -> 30
A9: 5 | B9: =Parameters!$B$9 -> 0.02 | C9: Five up | D9: Executive | E9: =$B9*80 -> 1.6 | F9: =$B9*1000 -> 20
A10: Total | B10: =SUM(B5:B9) -> 0.25 | C10: All five levels claimed at once | E10: =SUM(E5:E9) -> 20 | F10: =SUM(F5:F9) -> 250
A12: Why the spine never prorates | B12: Value
A13: Maximum the spine can claim from one source | B13: =B10 -> 0.25
A14: The pool available on that source (Law B) | B14: =Parameters!$B$16 -> 0.25
A15: Headroom left for layers 2 and 3 | B15: =B13-B14 -> 0
A16: Only one ancestor can occupy each level, so the spine's worst case is exactly 25 percent of CV: it always fits. Layers 2 and 3 are funded exclusively by what the spine did NOT claim, which is breakage: unreachable levels, unqualified earners, depth gates. The team-building money is reclaimed breakage and nothing else.
A18: Rounding rule | B18: Applies to
A19: Round half up to 2 decimals at the LINE level | B19: Every spine line, and any line no proration touched
A20: Round DOWN (floor) to 2 decimals | B20: Any line where at least one per-source piece was prorated
A21: Never re-round | B21: Member totals and company totals are sums of already-rounded lines

Sheet Layer 2 overrides
A1: Layer 2, Builder overrides
A2: Pays a member on the whole organization of each Builder they developed, two generations deep. No breakaway: no volume ever leaves anyone's group.
A4: Item | B4: Value
A5: Trigger | B5: Every downline member holding Builder rank or above this month, evaluated independently.
A6: Basis | B6: That Builder's GROUP CV: their own CV plus the CV of their entire subtree, full depth, nothing excluded.
A7: Generation 1 rate | B7: =Parameters!$B$10 -> 0.015
A8: Generation 2 rate | B8: =Parameters!$B$11 -> 0.01
A9: Generations paid | B9: Two. The walk stops when the boundary counter reaches 2, or at the root.
A10: Boundary | B10: A Builder or above. Generations here are counted by Builder-rank boundaries, not by tree levels.
A11: Earner gate | B11: Qualified. No rank of their own is required: the walk already demands a developed Builder below.
A12: Breakaway | B12: None. A nested Builder's group stays inside every enclosing group, so groups NEST.
A14: Step | B14: The walk, per Builder B, from B upward toward the root | C14: Counter
A15: 1 | B15: Start at B's sponsor with a boundary counter of 0. At each member: FIRST evaluate, THEN count. | C15: 0
A16: 2 | B16: EVALUATE: if the member is qualified AND the counter is 0 AND generation 1 is unassigned, they earn generation 1 rate times B's group CV. | C16: still 0
A17: 3 | B17: EVALUATE: else if the member is qualified AND the counter is 1 AND generation 2 is unassigned, they earn generation 2 rate times B's group CV. | C17: still 1
A18: 4 | B18: COUNT: if the member just evaluated holds Builder rank or above, add 1 to the counter. | C18: +1
A19: 5 | B19: STOP when the counter reaches 2, or at the root. | C19: 2
A21: Consequence of the walk | B21: Detail
A22: Generation 1 normally goes to the sponsor | B22: Precisely: to the first QUALIFIED member above B with no Builder in between.
A23: An unqualified member is skipped entirely | B23: Passed over without earning and without incrementing the counter.
A24: Generation 2 exists only when | B24: A Builder or above sits between B and the generation 2 recipient.
A25: One member can hold both | B25: Generation 1 for one Builder and generation 2 for a deeper one, in the same month.
A26: Developing a Builder costs the upline nothing | B26: There is no rank a downline can reach that removes a cent of volume from anyone above them.
A28: Honest consequence, stated rather than hidden: because groups nest, one source member's CV can back override claims for several enclosing Builders at once. Layer 2 is therefore NOT bounded by its rates. The Law B waterfall is the ceiling, and it is absolute.

Sheet Layer 3 second leg
A1: Layer 3, the second-leg bonus
A2: Pays on the SECOND-strongest leg. One giant leg pays nothing extra, by construction.
A4: Item | B4: Value
A5: Eligibility | B5: Qualified AND at least 2 ACTIVE legs this month.
A6: Basis | B6: The CV of the second-strongest leg, ranked by leg CV descending, ties broken by frontline member id ascending.
A7: Base rate | B7: =Parameters!$B$12 -> 0.02
A8: Ranking universe | B8: ALL legs, by CV. Qualification is irrelevant to leg CV: volume is volume.
A9: Multiplier universe | B9: ACTIVE legs only. So a member with two active legs and a fat inactive third is still paid on the second-strongest by volume.
A10: Lines produced | B10: One per earner. No source member, no level: the basis is an aggregate, like binary's pay leg.
A11: Carryover | B11: None. Nothing banks month to month.
A13: Active legs | B13: Multiplier | C13: Effective rate | D13: On a second leg of 1,000.00 CV
A14: 2 active legs | B14: =Parameters!$B$13 -> 1 | C14: =Parameters!$B$12*B14 -> 0.02 | D14: =C14*1000 -> 20
A15: 3 active legs | B15: =Parameters!$B$14 -> 1.15 | C15: =Parameters!$B$12*B15 -> 0.023 | D15: =C15*1000 -> 23
A16: 4 or more active legs | B16: =Parameters!$B$15 -> 1.25 | C16: =Parameters!$B$12*B16 -> 0.025 | D16: =C16*1000 -> 25
A17: fewer than 2 | B17: n/a | C17: Ineligible | D17: -
A19: The dilution test: why splitting volume across more legs loses | B19: Legs (k) | C19: Multiplier | D19: Pays, per unit of downline volume V
A20: Everything in one leg | B20: 1 | C20: n/a | D20: 0
A21: Two balanced legs: the optimum | B21: 2 | C21: =Parameters!$B$13 -> 1 | D21: =Parameters!$B$12*C21/B21 -> 0.01
A22: Three balanced legs | B22: 3 | C22: =Parameters!$B$14 -> 1.15 | D22: =Parameters!$B$12*C22/B22 -> 0.0076666667
A23: Four balanced legs | B23: 4 | C23: =Parameters!$B$15 -> 1.25 | D23: =Parameters!$B$12*C23/B23 -> 0.00625
A24: The multiplier softens the dilution but never reverses it: multiplier(k) divided by k must strictly decrease in k, so shell legs strictly lose. And shell legs cannot even be counted, because the multiplier counts ACTIVE legs, which require real qualified frontline members.

Sheet Law B waterfall
A1: Law B: the per-order cap
A2: Computed per source member-month, as closed formulas over the complete claim set. No enumeration order can change any factor.
A4: Step | B4: Quantity | C4: Formula | D4: Rule
A5: 1 | B5: Pool | C5: pool = pool rate x CV of the source | D5: The most that source can ever pay out, all layers combined.
A6: 2 | B6: Spine paid | C6: sum of the level rates that actually reached | D6: Paid in full, always. It cannot exceed the pool.
A7: 3 | B7: Remainder after spine | C7: R2 = pool - spine paid | D7: Everything layer 2 and layer 3 have to share.
A8: 4 | B8: Layer 2 factor | C8: f2 = 1 if L2 claims fit, else R2 / L2 claims | D8: Generations 1 and 2 share one class, pro rata.
A9: 5 | B9: Layer 2 paid | C9: each claim x f2 | D9: Truncated at 6 decimals, so paid can never exceed pool.
A10: 6 | B10: Remainder after layer 2 | C10: R3 = R2 - layer 2 paid | D10: What is left for the bonus.
A11: 7 | B11: Layer 3 factor | C11: f3 = min(1, R3 / L3 claims) | D11: Same rule, one step junior.
A12: 8 | B12: Layer 3 paid | C12: each claim x f3 | D12: Truncated at 6 decimals.
A14: The invariant, recomputed per source on every run | B14: Value
A15: spine paid + layer 2 paid + layer 3 paid, for every source, is at most | B15: =Parameters!$B$16 -> 0.25
A16: Expressed against the money the customer paid | B16: =Parameters!$B$16*Parameters!$B$18 -> 0.2
A17: CV is 0.80 of SV and PV equals dollars, so a pool of 25 percent of CV is exactly 20 percent of revenue: the ceiling the live plan already promises publicly. This plan does not raise the ceiling. It spends the headroom under it.
A19: What this rules out | B19: How
A20: Cost drift discovered in the accounts months later | B20: The cap is enforced inside the calculation, per order, not monitored after the fact.
A21: Wrong parameters breaking the bank | B21: Even wildly wrong rates cannot breach the pool. Law B holds regardless of parameters.
A22: Waterfall arbitrage | B22: Claims attach to sources by tree position, not by earner choice. Factors are per-source facts.
A23: Ordering effects | B23: The factors are closed formulas over the complete claim sets, never a sequential drain of a ledger.
A25: The one thing this costs, stated plainly | B25: Detail
A26: A prorated line is not recomputable by the member | B26: It depends on OTHER people's claims on shared sources, per source, at 6 decimals.
A27: So the plan requires, as a rule | B27: Every prorated line must print the CLAIMED amount, the PAID amount, and a one-line reason. A member-facing surface without it fails its gate.

Sheet Worked example
A1: The ten-member gate fixture, computed live
A2: At the DRAFT rates by contract: this fixture is the gate, and every run records the rates it used. Change a draft rate on Parameters and every figure below moves.
A4: Member | B4: Sponsor | C4: CV | D4: Qualified | E4: Rank | F4: Paid depth | G4: Why that rank
A5: M1 | B5: root | C5: 160 | D5: yes | E5: Leader | F5: 3 | G5: TV 2,500 exactly, and 3 active legs (M2, M3, M4)
A6: M2 | B6: M1 | C6: 120 | D6: yes | E6: Member | F6: 1 | G6: Only 1 active leg: M5 is unqualified, M6 is qualified
A7: M3 | B7: M1 | C7: 80 | D7: yes | E7: Builder | F7: 2 | G7: SV 100 exactly, and 2 active legs (M7, M8)
A8: M4 | B8: M1 | C8: 80 | D8: yes | E8: Member | F8: 1 | G8: No legs
A9: M5 | B9: M2 | C9: 40 | D9: no | E9: Member | F9: 1 | G9: SV 50, below the gate
A10: M6 | B10: M2 | C10: 120 | D10: yes | E10: Member | F10: 1 | G10: No legs
A11: M7 | B11: M3 | C11: 1200 | D11: yes | E11: Member | F11: 1 | G11: No legs
A12: M8 | B12: M3 | C12: 80 | D12: yes | E12: Member | F12: 1 | G12: Its only leg, M10, is unqualified: 0 active legs
A13: M9 | B13: M5 | C13: 240 | D13: yes | E13: Member | F13: 1 | G13: No legs
A14: M10 | B14: M8 | C14: 40 | D14: no | E14: Member | F14: 1 | G14: SV 50, below the gate
A15: Total | C15: =SUM(C5:C14) -> 2160
A17: The waterfall, source by source
A18: Source | B18: CV | C18: Spine rates that reached | D18: Which ancestors | E18: Pool | F18: Spine paid | G18: In M3 group? | H18: Layer 2 claim | I18: R2 | J18: f2 | K18: Layer 2 paid | L18: In M1 2nd leg? | M18: In M3 2nd leg? | N18: Layer 3 claim | O18: R3 | P18: f3 | Q18: Layer 3 paid | R18: Total paid | S18: Cap
A19: M1 | B19: =INDEX($C$5:$C$14,MATCH(A19,$A$5:$A$14,0)) -> 160 | C19: 0 | D19: root, nobody above | E19: =Parameters!$B$16*B19 -> 40 | F19: =C19*B19 -> 0 | G19: 0 | H19: =G19*Parameters!$C$10*B19 -> 0 | I19: =E19-F19 -> 40 | J19: =IF(H19=0,1,TRUNC(MIN(1,I19/H19),6)) -> 1 | K19: =TRUNC(H19*J19,6) -> 0 | L19: 0 | M19: 0 | N19: =(L19*Parameters!$C$12*Parameters!$C$14+M19*Parameters!$C$12)*B19 -> 0 | O19: =I19-K19 -> 40 | P19: =IF(N19=0,1,TRUNC(MIN(1,O19/N19),6)) -> 1 | Q19: =TRUNC(N19*P19,6) -> 0 | R19: =F19+K19+Q19 -> 0 | S19: =IF(R19<=E19+0.0000001,"holds","BREACH") -> holds
A20: M2 | B20: =INDEX($C$5:$C$14,MATCH(A20,$A$5:$A$14,0)) -> 120 | C20: 0.1 | D20: M1 at level 1 | E20: =Parameters!$B$16*B20 -> 30 | F20: =C20*B20 -> 12 | G20: 0 | H20: =G20*Parameters!$C$10*B20 -> 0 | I20: =E20-F20 -> 18 | J20: =IF(H20=0,1,TRUNC(MIN(1,I20/H20),6)) -> 1 | K20: =TRUNC(H20*J20,6) -> 0 | L20: 1 | M20: 0 | N20: =(L20*Parameters!$C$12*Parameters!$C$14+M20*Parameters!$C$12)*B20 -> 6.9 | O20: =I20-K20 -> 18 | P20: =IF(N20=0,1,TRUNC(MIN(1,O20/N20),6)) -> 1 | Q20: =TRUNC(N20*P20,6) -> 6.9 | R20: =F20+K20+Q20 -> 18.9 | S20: =IF(R20<=E20+0.0000001,"holds","BREACH") -> holds
A21: M3 | B21: =INDEX($C$5:$C$14,MATCH(A21,$A$5:$A$14,0)) -> 80 | C21: 0.1 | D21: M1 at level 1 | E21: =Parameters!$B$16*B21 -> 20 | F21: =C21*B21 -> 8 | G21: 1 | H21: =G21*Parameters!$C$10*B21 -> 3.2 | I21: =E21-F21 -> 12 | J21: =IF(H21=0,1,TRUNC(MIN(1,I21/H21),6)) -> 1 | K21: =TRUNC(H21*J21,6) -> 3.2 | L21: 0 | M21: 0 | N21: =(L21*Parameters!$C$12*Parameters!$C$14+M21*Parameters!$C$12)*B21 -> 0 | O21: =I21-K21 -> 8.8 | P21: =IF(N21=0,1,TRUNC(MIN(1,O21/N21),6)) -> 1 | Q21: =TRUNC(N21*P21,6) -> 0 | R21: =F21+K21+Q21 -> 11.2 | S21: =IF(R21<=E21+0.0000001,"holds","BREACH") -> holds
A22: M4 | B22: =INDEX($C$5:$C$14,MATCH(A22,$A$5:$A$14,0)) -> 80 | C22: 0.1 | D22: M1 at level 1 | E22: =Parameters!$B$16*B22 -> 20 | F22: =C22*B22 -> 8 | G22: 0 | H22: =G22*Parameters!$C$10*B22 -> 0 | I22: =E22-F22 -> 12 | J22: =IF(H22=0,1,TRUNC(MIN(1,I22/H22),6)) -> 1 | K22: =TRUNC(H22*J22,6) -> 0 | L22: 0 | M22: 0 | N22: =(L22*Parameters!$C$12*Parameters!$C$14+M22*Parameters!$C$12)*B22 -> 0 | O22: =I22-K22 -> 12 | P22: =IF(N22=0,1,TRUNC(MIN(1,O22/N22),6)) -> 1 | Q22: =TRUNC(N22*P22,6) -> 0 | R22: =F22+K22+Q22 -> 8 | S22: =IF(R22<=E22+0.0000001,"holds","BREACH") -> holds
A23: M5 | B23: =INDEX($C$5:$C$14,MATCH(A23,$A$5:$A$14,0)) -> 40 | C23: 0.15 | D23: M2 level 1, M1 level 2 | E23: =Parameters!$B$16*B23 -> 10 | F23: =C23*B23 -> 6 | G23: 0 | H23: =G23*Parameters!$C$10*B23 -> 0 | I23: =E23-F23 -> 4 | J23: =IF(H23=0,1,TRUNC(MIN(1,I23/H23),6)) -> 1 | K23: =TRUNC(H23*J23,6) -> 0 | L23: 1 | M23: 0 | N23: =(L23*Parameters!$C$12*Parameters!$C$14+M23*Parameters!$C$12)*B23 -> 2.3 | O23: =I23-K23 -> 4 | P23: =IF(N23=0,1,TRUNC(MIN(1,O23/N23),6)) -> 1 | Q23: =TRUNC(N23*P23,6) -> 2.3 | R23: =F23+K23+Q23 -> 8.3 | S23: =IF(R23<=E23+0.0000001,"holds","BREACH") -> holds
A24: M6 | B24: =INDEX($C$5:$C$14,MATCH(A24,$A$5:$A$14,0)) -> 120 | C24: 0.15 | D24: M2 level 1, M1 level 2 | E24: =Parameters!$B$16*B24 -> 30 | F24: =C24*B24 -> 18 | G24: 0 | H24: =G24*Parameters!$C$10*B24 -> 0 | I24: =E24-F24 -> 12 | J24: =IF(H24=0,1,TRUNC(MIN(1,I24/H24),6)) -> 1 | K24: =TRUNC(H24*J24,6) -> 0 | L24: 1 | M24: 0 | N24: =(L24*Parameters!$C$12*Parameters!$C$14+M24*Parameters!$C$12)*B24 -> 6.9 | O24: =I24-K24 -> 12 | P24: =IF(N24=0,1,TRUNC(MIN(1,O24/N24),6)) -> 1 | Q24: =TRUNC(N24*P24,6) -> 6.9 | R24: =F24+K24+Q24 -> 24.9 | S24: =IF(R24<=E24+0.0000001,"holds","BREACH") -> holds
A25: M7 | B25: =INDEX($C$5:$C$14,MATCH(A25,$A$5:$A$14,0)) -> 1200 | C25: 0.15 | D25: M3 level 1, M1 level 2 | E25: =Parameters!$B$16*B25 -> 300 | F25: =C25*B25 -> 180 | G25: 1 | H25: =G25*Parameters!$C$10*B25 -> 48 | I25: =E25-F25 -> 120 | J25: =IF(H25=0,1,TRUNC(MIN(1,I25/H25),6)) -> 1 | K25: =TRUNC(H25*J25,6) -> 48 | L25: 0 | M25: 0 | N25: =(L25*Parameters!$C$12*Parameters!$C$14+M25*Parameters!$C$12)*B25 -> 0 | O25: =I25-K25 -> 72 | P25: =IF(N25=0,1,TRUNC(MIN(1,O25/N25),6)) -> 1 | Q25: =TRUNC(N25*P25,6) -> 0 | R25: =F25+K25+Q25 -> 228 | S25: =IF(R25<=E25+0.0000001,"holds","BREACH") -> holds
A26: M8 | B26: =INDEX($C$5:$C$14,MATCH(A26,$A$5:$A$14,0)) -> 80 | C26: 0.15 | D26: M3 level 1, M1 level 2 | E26: =Parameters!$B$16*B26 -> 20 | F26: =C26*B26 -> 12 | G26: 1 | H26: =G26*Parameters!$C$10*B26 -> 3.2 | I26: =E26-F26 -> 8 | J26: =IF(H26=0,1,TRUNC(MIN(1,I26/H26),6)) -> 1 | K26: =TRUNC(H26*J26,6) -> 3.2 | L26: 0 | M26: 1 | N26: =(L26*Parameters!$C$12*Parameters!$C$14+M26*Parameters!$C$12)*B26 -> 4 | O26: =I26-K26 -> 4.8 | P26: =IF(N26=0,1,TRUNC(MIN(1,O26/N26),6)) -> 1 | Q26: =TRUNC(N26*P26,6) -> 4 | R26: =F26+K26+Q26 -> 19.2 | S26: =IF(R26<=E26+0.0000001,"holds","BREACH") -> holds
A27: M9 | B27: =INDEX($C$5:$C$14,MATCH(A27,$A$5:$A$14,0)) -> 240 | C27: 0.05 | D27: M1 level 3 only | E27: =Parameters!$B$16*B27 -> 60 | F27: =C27*B27 -> 12 | G27: 0 | H27: =G27*Parameters!$C$10*B27 -> 0 | I27: =E27-F27 -> 48 | J27: =IF(H27=0,1,TRUNC(MIN(1,I27/H27),6)) -> 1 | K27: =TRUNC(H27*J27,6) -> 0 | L27: 1 | M27: 0 | N27: =(L27*Parameters!$C$12*Parameters!$C$14+M27*Parameters!$C$12)*B27 -> 13.8 | O27: =I27-K27 -> 48 | P27: =IF(N27=0,1,TRUNC(MIN(1,O27/N27),6)) -> 1 | Q27: =TRUNC(N27*P27,6) -> 13.8 | R27: =F27+K27+Q27 -> 25.8 | S27: =IF(R27<=E27+0.0000001,"holds","BREACH") -> holds
A28: M10 | B28: =INDEX($C$5:$C$14,MATCH(A28,$A$5:$A$14,0)) -> 40 | C28: 0.2 | D28: M8 L1, M3 L2, M1 L3 | E28: =Parameters!$B$16*B28 -> 10 | F28: =C28*B28 -> 8 | G28: 1 | H28: =G28*Parameters!$C$10*B28 -> 1.6 | I28: =E28-F28 -> 2 | J28: =IF(H28=0,1,TRUNC(MIN(1,I28/H28),6)) -> 1 | K28: =TRUNC(H28*J28,6) -> 1.6 | L28: 0 | M28: 1 | N28: =(L28*Parameters!$C$12*Parameters!$C$14+M28*Parameters!$C$12)*B28 -> 2 | O28: =I28-K28 -> 0.4 | P28: =IF(N28=0,1,TRUNC(MIN(1,O28/N28),6)) -> 0.2 | Q28: =TRUNC(N28*P28,6) -> 0.4 | R28: =F28+K28+Q28 -> 10 | S28: =IF(R28<=E28+0.0000001,"holds","BREACH") -> holds
A29: Total | B29: =SUM(B19:B28) -> 2160 | E29: =SUM(E19:E28) -> 540 | F29: =SUM(F19:F28) -> 264 | H29: =SUM(H19:H28) -> 56 | K29: =SUM(K19:K28) -> 56 | N29: =SUM(N19:N28) -> 35.9 | Q29: =SUM(Q19:Q28) -> 34.3 | R29: =SUM(R19:R28) -> 354.3 | S29: =IF(COUNTIF(S19:S28,"BREACH")=0,"all hold","BREACH") -> all hold
A30: M10 is the law at its boundary, not in its slack: pool 10.00, spine 8.00, override piece 1.60, leaving 0.40 against a 2.00 bonus claim. f3 becomes 0.200000 and the source pays exactly its cap.
A32: Who gets paid, and what the layers cost
A33: Earner | B33: Layer | C33: Basis | D33: Rate | E33: Claimed | F33: Paid | G33: Note
A34: M1 | B34: Layer 1 spine | E34: 114 | F34: =E34 -> 114 | G34: Levels 1 to 3 on nine sources
A35: M1 | B35: Layer 2 generation 1 | C35: 1400 | D35: =Parameters!$C$10 -> 0.04 | E35: =C35*D35 -> 56 | F35: =E35 -> 56 | G35: On Builder M3's group CV. No proration touched it.
A36: M1 | B36: Layer 3 second-leg bonus | C36: 520 | D36: =Parameters!$C$12*Parameters!$C$14 -> 0.0575 | E36: =C36*D36 -> 29.9 | F36: =E36 -> 29.9 | G36: Second-strongest leg is the M2 leg. 3 active legs, so the multiplier is 1.15.
A37: M2 | B37: Layer 1 spine | E37: 16 | F37: =E37 -> 16 | G37: Level 1 on M5 and M6. Depth 1 stops there.
A38: M3 | B38: Layer 1 spine | E38: 130 | F38: =E38 -> 130 | G38: Levels 1 to 2.
A39: M3 | B39: Layer 3 second-leg bonus | C39: 120 | D39: =Parameters!$C$12 -> 0.05 | E39: =C39*D39 -> 6 | F39: =ROUNDDOWN(Q26+Q28,2) -> 4.4 | G39: SHAVED. The M10 piece prorated from 2.00 to 0.40, so the whole line is floored.
A40: M8 | B40: Layer 1 spine | E40: 4 | F40: =E40 -> 4 | G40: Level 1 on M10.
A41: M4, M5, M6, M7, M9, M10 | B41: Nothing | E41: 0 | F41: 0 | G41: Four of ten members are paid. Everything else is breakage.
A42: Company | B42: All three layers | E42: =SUM(E34:E41) -> 355.9 | F42: =SUM(F34:F41) -> 354.3 | G42: Must equal the waterfall's total paid.
A44: Check | B44: Value | C44: Must be
...

Sheet Cap calculator
A1: What one order can ever pay
A2: Change the blue cell. Everything else follows.
A4: Input | B4: Value
A5: Order price, in dollars | B5: 100
A7: Derived | B7: Value | C7: How
A8: Personal Volume (PV) | B8: =B5 -> 100 | C8: PV equals dollars, one to one
A9: Sales Volume (SV) | B9: =B5 -> 100 | C9: One order, so SV equals the PV
A10: Commissionable Volume (CV) | B10: =ROUND(B5*Parameters!$B$18,2) -> 80 | C10: CV factor times SV, rounded half up
A11: Qualifies the buyer? | B11: =IF(B5>=Parameters!$B$17,"yes","no, needs 100.00 SV") -> yes | C11: The single gate
A12: THE POOL: the most this order can ever pay | B12: =Parameters!$B$16*B10 -> 20 | C12: Pool rate times CV. All layers, all people, combined.
A13: The same, as a share of the price | B13: =B12/B5 -> 0.2 | C13: This is the 20 percent the company already promises
A14: Spine's maximum bite, if all five levels reach | B14: =B10*SUM(Parameters!$B$5:$B$9) -> 20 | C14: Only one ancestor can sit at each level
A15: Left for layers 2 and 3 in that worst case | B15: =B12-B14 -> 0 | C15: Zero. Which is why the spine can never be prorated.
A17: If the spine only partly reaches | B17: Spine paid | C17: Left for layers 2 and 3
A18: All five levels reach | B18: =B10*0.25 -> 20 | C18: =B12-B18 -> 0
A19: Levels 1 to 3 reach | B19: =B10*0.2 -> 16 | C19: =B12-B19 -> 4
A20: Levels 1 and 2 reach | B20: =B10*0.15 -> 12 | C20: =B12-B20 -> 8
A21: Level 1 only | B21: =B10*0.1 -> 8 | C21: =B12-B21 -> 12
A22: Nobody above is qualified | B22: =B10*0 -> 0 | C22: =B12-B22 -> 20
A23: The right-hand column is the team-building budget. It is breakage and nothing else: money the spine did not reach. Layers 2 and 3 spend it, and can never spend more than it.

Sheet Measured results
A1: What the plan actually paid
A2: Seeded census, calibrated rates of record. These figures are refreshed per run and must be carried in any presentation of the plan.
A4: Month | B4: Payout as a percent of CV | C4: Headroom left under the ceiling
A5: February | B5: 0.185594 | C5: =0.25-B5 -> 0.064406
A6: March | B6: 0.189399 | C6: =0.25-B6 -> 0.060601
A7: April | B7: 0.191224 | C7: =0.25-B7 -> 0.058776
A8: May | B8: 0.194412 | C8: =0.25-B8 -> 0.055588
A9: June | B9: 0.195434 | C9: =0.25-B9 -> 0.054566
A10: July | B10: 0.196812 | C10: =0.25-B10 -> 0.053188
A11: Rise over five month-steps | B11: =B10-B5 -> 0.011218 | C11: About 0.22 points a month at this field maturity
A12: The live baseline plan, March | B12: 0.146085 | C12: The spine alone
A13: The hard ceiling | B13: 0.25 | C13: Law B. Unreachable by construction.
A14: August is excluded on purpose: eleven bridged orders and two members paid is evidence of nothing. The drift is real and intended, the plan pays more as the field develops, and it is bounded above.
A16: Proration: how hard the cap is working | B16: Count | C16: Of | D16: Share
A17: Sources prorated on at least one layer | B17: 154 | C17: 641 | D17: =B17/C17 -> 0.24024961
A18: Of those, binding at layer 2 | B18: 120 | C18: 641 | D18: =B18/C18 -> 0.18720749
A19: Of those, binding at layer 3 | B19: 83 | C19: 641 | D19: =B19/C19 -> 0.12948518
A20: Binding ONLY at layer 3 | B20: 34 | C20: 641 | D20: =B20/C20 -> 0.053042122
A21: Paid members carrying at least one shaved line | B21: 35 | C21: 207 | D21: =B21/C21 -> 0.16908213
A22: The denominator is 641, the sources that carry any volume. 360 census sources have zero volume and can never bind, so including them understates the rate. Proration is ROUTINE AND JUNIOR: a working feature, not an edge case.
A24: Amounts prorated away | B24: Value
A25: Shaved off layer 2 | B25: 638
A26: Shaved off layer 3 | B26: 305.68
A27: Total shaved | B27: =B25+B26 -> 943.68
A28: Total paid in the run | B28: 17417.12
A29: Shaved as a share of the run | B29: =B27/B28 -> 0.054181173
A30: Worst single member shaved | B30: 324.14
A31: Worst ratio, against claims the cap can reach | B31: 0.345
A32: Members who lost 100 percent of their structure claims | B32: 5
A33: The spine is never shaved, so no member's live-plan-equivalent pay is ever reduced. The five members who lost everything lost sums of 1.60 to 5.52, all of it from layers 2 and 3.
A35: The development premium: same volume, different structure | B35: Developed a Builder | C35: Did not | D35: Multiple | E35: n, with | F35: n, without
A36: SV band 100 to 149 | B36: 52.47 | C36: 6.66 | D36: =B36/C36 -> 7.8783784 | E36: 8 | F36: 141
A37: SV band 150 to 299 | B37: 725.57 | C37: 7.9 | D37: =B37/C37 -> 91.844304 | E37: 8 | F37: 186
A38: SV band 300 and above | B38: 955.31 | C38: 11.77 | D38: =B38/C38 -> 81.164826 | E38: 8 | F38: 97
A39: The premium is NOT monotone in the band: it runs 7.9x, 92x, 81x, so the TOP band is 81x and the sentence 'up to 92 times at the top' is false. Quote the three band multiples, never a range.
A41: Participation, quoted in the same breath | B41: Value
A42: Members who personally sponsored at least one Builder | B42: 34
A43: Of those, also qualified that month (the earnings population) | B43: 24
A44: Members who earn any structure money at all | B44: 44
A45: Share of the structure budget taken by the top five | B45: 0.902
...

Sheet Guardrails
A1: Anti-gaming arithmetic
A2: Every known attack, priced. Engine-measured at the rates of record.
A4: Attack | B4: Monthly cost | C4: Monthly yield | D4: Returned per dollar | E4: Verdict
A5: Fund a puppet downline into Builder rank | B5: 300 | C5: 21.2 | D5: =C5/B5 -> 0.070666667 | E5: 92.9 percent monthly loss, forever: decay makes the puppet a subscription, not a purchase
A6: Fund an artificial second leg to unlock the bonus | B6: 100 | C6: 2 | D6: =C6/B6 -> 0.02 | E6: 98 percent monthly loss, forever, re-priced every month
A7: Split downline volume across more legs | E7: Loses. See the dilution test on Layer 3 second leg: two balanced legs is the optimum.
A8: Stack everyone into one leg | E8: Pays nothing extra by construction: with one leg there is no second leg.
A9: Buy rank with one large purchase | E9: Blocked: a one-time purchase is spread over ten months, so $2,000 arrives as 200 PV a month, not 2,000 once.
A10: Create shell legs to lift the multiplier | E10: Blocked: the multiplier counts ACTIVE legs, which need real qualified frontline members.
A11: Route claims toward richer pools | E11: Impossible: claims attach to sources by tree position, not by earner choice.
A12: Sandbag the strong leg, bank the volume | E12: Nothing to bank: no carryover, no placement tree. Volume books to the account that bought it, monthly.
A14: Bound | B14: Value | C14: Scope, stated exactly
A15: Most commission a self-funded dollar can generate | B15: 0.2 | C15: Bounds commission generated BY the self-funded volume itself. It does NOT bound volume bought to UNLOCK pay on other people's volume, which is what the 100.00 qualification gate does.
A17: The one finding that survived, kept and named
A18: The lapse-benefit inversion | B18: Detail
A19: What happens | B19: Above a pool-binding stack, a downline Builder's lapse RAISES senior checks, because the lapse frees capacity in bound pools and the relief flows to everyone else claiming those sources.
A20: Measured | B20: In the hostile fixture, one mid-stack Builder lapses, the field loses 100.00 SV of real revenue, and SIX checks rise. The top earner gains 7.44 on a 212.91 check.
A21: Who still loses | B21: The two nearest Builder generations, hard, and the lapsed member entirely. The people positioned to intervene still have the right incentive.
A22: Can it be farmed? | B22: No. A member cannot make a downline lapse, only decline to help one recover. No active construction extracts it.
A23: Is it new money? | B23: No. It is exactly the freed share of already-bound pools, and company cost goes DOWN on every lapse.
A24: How it is handled | B24: Named in the plan, bounded by Law B, and watched every run as a standing metric. Never rediscovered.

Sheet Open items
A1: Still on default, waiting on a ruling
A2: Each one is a parameter, not a redesign.
A4: # | B4: Question | C4: Current default | D4: The alternative
A5: 1 | B5: Pool rate: 25 percent of CV, or a literal 20 percent of CV? | C5: 0.25 of CV, which is 20 percent of revenue | D5: A 20-percent-of-CV pool would force the SPINE itself to prorate, since its five levels claim up to 25 percent.
A6: 2 | B6: Do generations 1 and 2 share one proration class? | C6: Yes, one class, pro rata | D6: Make generation 1 senior to generation 2.
A7: 3 | B7: Must a layer 2 earner hold Builder rank themselves? | C7: No, qualified only | D7: Require Builder or above to earn generation 2, a 'match your depth' flavour.
A8: 4 | B8: Are legs ranked over all legs, or active legs only? | C8: All legs, by CV | D8: Rank over active legs only.
A9: 5 | B9: The multiplier values 1.00 / 1.15 / 1.25 | C9: As drafted | D9: Any change must keep multiplier(k) divided by k strictly decreasing, or the dilution argument breaks.
A10: 6 | B10: The calibration budget: 2.0 to 4.0 points of CV above baseline | C10: As drafted. Realized 4.3314, which is 0.33 above the ceiling, accepted and displayed | D10: Name a different budget, or shave one rate a half-step.
A11: 7 | B11: A member-facing name for the plan | C11: Lab code 'orvanna_builder' only | D11: Needs a field name and a booklet if it ever leaves the lab.
A12: 8 | B12: A one-month Builder grace after a lapse | C12: No grace. Monthly-pure, like everything else | D12: Grace would blunt the near-upline's retention incentive and would do NOTHING about the lapse-benefit inversion, which lives in the waterfall, not in rank decay.
A13: ! | B13: The 20 percent ceiling versus the approved Instant Payout terms. A known contradiction, on the record rather than left as a trap. | C13: Not built. It pays nothing today. | D13: Instant Payout was approved at 20 percent of the order price and does not roll up to the upline. On a self-funded first order of 150.00 that returns 42.00, which is 28 cents on the dollar against a 20 percent ceiling: eight points over. Reconciling the two is the gate on ever building it.
